<?xml version="1.0"?>
<robot name="dummy" xmlns:xacro="http://ros.org/wiki/xacro">
  <xacro:include filename="$(find cybergear_control)/description/ros2_control/1dof.ros2_control.urdf.xacro"/>
  <!-- Base Link -->
  <link name="base_link">
    <visual>
      <geometry>
        <box size="0.2 0.2 0.1" />
      </geometry>
      <material name="Blue">
        <color rgba="0 0 1 1" />
      </material>
    </visual>
    <collision>
      <geometry>
        <box size="0.2 0.2 0.1" />
      </geometry>
    </collision>
  </link>

  <!-- Wheel Link -->
  <link name="wheel_link">
    <visual>
      <geometry>
        <cylinder length="0.1" radius="0.2" />
      </geometry>
      <material name="Black">
        <color rgba="0.1 0.1 0.1 1" />
      </material>
    </visual>
    <collision>
      <geometry>
        <cylinder length="0.1" radius="0.18" />
      </geometry>
    </collision>
    <inertial>
      <mass value="0.5" />
      <inertia ixx="0.01" ixy="0.0" ixz="0.0" iyy="0.01" iyz="0.0" izz="0.005" />
    </inertial>
  </link>

  <!-- Rotational Joint -->
  <joint name="wheel_joint" type="continuous">
    <parent link="base_link"/>
    <child link="wheel_link"/>
    <origin xyz="0 0.18 0" rpy="1.5708 0 0"/>
    <axis xyz="0 0 1"/>
  </joint>

  <xacro:single_dof_ros2_control name="CybergearMotorWheelJoint1"/>

</robot>
